Workbook

Sheet Calculator
L3: [Hide this column] | M3: [Hide this column] | N3: [Hide this column] | R3: [Hide this column] | V3: [Hide this column] | W3: [Hide this column] | X3: [Hide this column] | Y3: [Hide this column] | Z3: [Hide this column] | AA3: [Hide this column] | AB3: [Hide this column] | AC3: [Hide this column] | AD3: [Hide this column] | AE3: [Hide this column] | AF3: [Hide this column] | AG3: [Hide this column] | AH3: [Hide this column] | AI3: [Hide this column] | AJ3: [Hide this column] | AK3: [Hide this column] | AL3: [Hide this column] | AM3: [Hide this column] | AN3: [Hide this column] | AO3: [Hide this column] | AP3: [Hide this column] | AQ3: [Hide this column] | AR3: [Hide this column] | AS3: [Hide this column] | AT3: [Hide this column] | AU3: [Hide this column] | AV3: [Hide this column] | AW3: [Hide this column] | AX3: [Hide this column]
D4: Evaluate-STIG Annual Projected Time and Cost Avoidance Over DISA and NIWC Enhanced SCAP Updated: 8/13/2025 | G4: Instructions: 1. Enter your hourly rate and average labor minutes to complete a single manual check. 2. Enter the total number of instances for each STIG-applicable product installed in your environment(s).
G5: * Annual projections assume quarterly reviews. | L5: [Hide this column] | M5: [Hide this column] | N5: [Hide this column] | R5: [Hide this column] | V5: [Hide this column] | W5: [Hide this column] | X5: [Hide this column] | Y5: [Hide this column] | Z5: [Hide this column] | AA5: [Hide this column] | AB5: [Hide this column]
D6: ="Note: First STIG in list is '"&(D12)&"' so make sure you're scrolled to the top!" -> Note: First STIG in list is 'Active Directory Domain' so make sure you're scrolled to the top! | G6: Projected: Annual Labor Hour Avoidance Over DISA SCAP with Evaluate-STIG | H6: Projected: Annual Cost Avoidance Over DISA SCAP with Evaluate-STIG | I6: Projected: Annual Labor Hour Avoidance Over NIWC Enhanced SCAP with Evaluate-STIG | J6: Projected: Annual Cost Avoidance Over NIWC Enhanced SCAP with Evaluate-STIG | K6: Total STIG Checks | L6: Total Automated Checks: DISA SCAP | M6: Total Automated Checks: NIWC Enhanced SCAP | N6: Total Automated Checks: Evaluate-STIG | O6: Total Remaining Manual Checks: DISA SCAP | P6: Total Remaining Manual Checks: NIWC Enhanced SCAP | Q6: Total Remaining Manual Checks: Evaluate-STIG | R6: Total Time to Complete per Quarter: Manual | S6: Total Assignable Labor Time for STIG Review (8 hr/Day): DISA SCAP | T6: Total Assignable Labor Time for STIG Review (8 hr/Day): NIWC Enhanced SCAP | U6: Total Assignable Labor Time for STIG Review (8 hr/Day): Evaluate-STIG | V6: Weighted Productivity Gain: DISA SCAP vs Manual (Hidden) | W6: Weighted Productivity Gain: NIWC Enhanced SCAP vs Manual (Hidden) | X6: Weighted Productivity Gain: Evaluate-STIG vs Manual (Hidden) | Y6: Total Cost to Complete per Quarter: Manual (Hidden) | Z6: Total Cost to Complete per Quarter: DISA SCAP (Hidden) | AA6: Total Cost to Complete per Quarter: NIWC Enhanced SCAP (Hidden) | AB6: Total Cost to Complete per Quarter: Evaluate-STIG (Hidden)
D7: Step 1: Enter Hourly Rate | E7: 126 | G7: =SUM(G12:G117) -> 71967.3 | H7: =SUM(H12:H117) -> 9067879.8 | I7: =SUM(I12:I117) -> 45234.6 | J7: =SUM(J12:J117) -> 5699559.6 | K7: =SUM(K12:K117) -> 1540144 | L7: =SUM(L12:L117) -> 1266612 | M7: =SUM(M12:M117) -> 1355721 | N7: =SUM(N12:N117) -> 1506503 | ... Q7: =SUM(Q12:Q117) -> 33641 | R7: =FLOOR($AC118*3,1)&" Days"&TEXT(SUM($AC118-TIME(8,0,0)*FLOOR($AC118*3,1))," h")&" Hrs" -> 14438 Days 6 Hrs | S7: =FLOOR($AD118*3,1)&" Days"&TEXT(SUM($AD118-TIME(8,0,0)*FLOOR($AD118*3,1))," h")&" Hrs" -> 2564 Days 2 Hrs | T7: =FLOOR($AE118*3,1)&" Days"&TEXT(SUM($AE118-TIME(8,0,0)*FLOOR($AE118*3,1))," h")&" Hrs" -> 1728 Days 7 Hrs | U7: =FLOOR($AF118*3,1)&" Days"&TEXT(SUM($AF118-TIME(8,0,0)*FLOOR($AF118*3,1))," h")&" Hrs" -> 315 Days 3 Hrs | V7: =((((SUM($E12:$E117)/$AJ118)-((SUM($E12:$E117)/$AI118))))/((SUM($E12:$E117)/$AI118))) -> 4.6214696 | W7: =((((SUM($E12:$E117)/$AK118)-((SUM($E12:$E117)/$AI118))))/((SUM($E12:$E117)/$AI118))) -> 7.3331456 | X7: =((((SUM($E12:$E117)/$AL118)-((SUM($E12:$E117)/$AI118))))/((SUM($E12:$E117)/$AI118))) -> 42.165874 | Y7: =SUM(Y12:Y117) -> 14554361 | Z7: =SUM(Z12:Z117) -> 2584877.4 | AA7: =SUM(AA12:AA117) -> 1742797.4 | AB7: =SUM(AB12:AB117) -> 317907.45
D8: Average Labor Minutes Per Manual Check | E8: 4.5 | O8: Automated: | P8: Automated: | Q8: Automated:
O9: =$L7/$K7 -> 0.82239843 | P9: =$M7/$K7 -> 0.880256 | Q9: =$N7/$K7 -> 0.97815724
AC10: Time to Complete | AI10: Weighted Effort | AN10: Quarterly Cost to Complete | AT10: Quarterly Cost Avoided
D11: STIG Supported by Evaluate-STIG | E11: Step 2: Enter Total Installed Instances of Product | G11: Annual Labor Hour Avoidance Over DISA SCAP | H11: Annual Cost Avoidance Over DISA SCAP | I11: Annual Labor Hour Avoidance Over NIWC Enhanced SCAP | J11: Annual Cost Avoidance Over NIWC Enhanced SCAP | K11: STIG Checks | L11: Completed Checks: DISA SCAP | M11: Completed Checks: NIWC Enhanced SCAP | N11: Completed Checks: Evaluate-STIG | O11: Remaining "NR": DISA SCAP | P11: Remaining "NR": NIWC Enhanced SCAP | Q11: Remaining "NR": Evaluate-STIG | R11: Time to Complete STIG per Quarter: Manual | S11: Time to Complete STIG Review (8 hr/Day): DISA SCAP | T11: Time to Complete STIG Review (8 hr/Day): NIWC Enhanced SCAP | U11: Time to Complete STIG Review (8 hr/Day): Evaluate-STIG | V11: Productivity Gain: DISA SCAP vs Manual | W11: Productivity Gain: NIWC Enhanced SCAP vs Manual | X11: Productivity Gain: Evaluate-STIG vs Manual | Y11: Cost to Complete STIG per Quarter: Manual | Z11: Cost to Complete STIG per Quarter: DISA SCAP | AA11: Cost to Complete STIG per Quarter: NIWC Enhanced SCAP | AB11: Cost to Complete STIG per Quarter: Evaluate-STIG | AC11: Hours to Complete: Manual | AD11: Hours to Complete: DISA SCAP | AE11: Hours to Complete: NIWC Enhanced SCAP | AF11: Hours to Complete: Evaluate-STIG | AG11: Evaluate-STIG over DISA SCAP Reduction | AH11: Evaluate-STIG over NIWC Enhanced SCAP Reduction | AI11: Manual | AJ11: DISA SCAP | AK11: NIWC Enhanced SCAP | AL11: Evaluate-STIG | AO11: Q1 | AP11: Q2 | AQ11: Q3 | AR11: Q4 | AU11: Q1 | AV11: Q2 | AW11: Q3 | AX11: Q4
D12: =(STIG_Metrics!A12) -> Active Directory Domain | E12: 1 | G12: =IF(E12=0,"",(AG12*24)*4) -> 6 | H12: =IF(E12=0,"",PRODUCT($G12,$E$7)) -> 756 | I12: =IF(E12=0,"",(AH12*24)*4) -> 6 | J12: =IF(E12=0,"",PRODUCT($I12,$E$7)) -> 756 | K12: =IF($E12=0,"",(STIG_Metrics!E12)*$E12) -> 36 | L12: =IF($E12=0,"",(STIG_Metrics!F12)*$E12) -> 0 | M12: =IF($E12=0,"",(STIG_Metrics!G12)*$E12) -> 0 | N12: =IF($E12=0,"",(STIG_Metrics!H12)*$E12) -> 20 | O12: =IF($E12=0,"",(STIG_Metrics!E12-STIG_Metrics!F12)*$E12) -> 36 | P12: =IF($E12=0,"",(STIG_Metrics!E12-STIG_Metrics!G12)*$E12) -> 36 | Q12: =IF($E12=0,"",(STIG_Metrics!E12-STIG_Metrics!H12)*$E12) -> 16 | R12: =IF($E12=0,"",FLOOR($AC12*3,1)&" Days"&TEXT(SUM($AC12-TIME(8,0,0)*FLOOR($AC12*3,1))," h")&" Hrs") -> 0 Days 2 Hrs | S12: =IF($E12=0,"",FLOOR($AD12*3,1)&" Days"&TEXT(SUM($AD12-TIME(8,0,0)*FLOOR($AD12*3,1))," h")&" Hrs") -> 0 Days 2 Hrs | T12: =IF($E12=0,"",FLOOR($AE12*3,1)&" Days"&TEXT(SUM($AE12-TIME(8,0,0)*FLOOR($AE12*3,1))," h")&" Hrs") -> 0 Days 2 Hrs | U12: =IF($E12=0,"",FLOOR($AF12*3,1)& " Days"&TEXT(SUM($AF12-TIME(8,0,0)*FLOOR($AF12*3,1))," h") & " Hrs") -> 0 Days 1 Hrs | V12: =IF($E12=0,"",STIG_Metrics!R12) -> 0 | W12: =IF($E12=0,"",STIG_Metrics!S12) -> 0 | X12: =IF($E12=0,"",STIG_Metrics!T12) -> 1.25 | Y12: =IF($E12=0,"",((K12*$E$8/60)*$E$7)) -> 340.2 | Z12: =IF($E12=0,"",((O12*$E$8/60)*$E$7)) -> 340.2 | AA12: =IF($E12=0,"",((P12*$E$8/60)*$E$7)) -> 340.2 | AB12: =IF($E12=0,"",((Q12*$E$8/60)*$E$7)) -> 151.2 | AC12: =IF($E12=0,"",IF(STIG_Metrics!N12=60,0,($E12/STIG_Metrics!N12)/24)) -> 0.1125 | AD12: =IF($E12=0,"",IF(STIG_Metrics!O12=60,0,($E12/STIG_Metrics!O12)/24)) -> 0.1125 | AE12: =IF($E12=0,"",IF(STIG_Metrics!P12=60,0,($E12/STIG_Metrics!P12)/24)) -> 0.1125 | AF12: =IF($E12=0,"",IF(STIG_Metrics!Q12=60,0,($E12/STIG_Metrics!Q12)/24)) -> 0.05 | AG12: =IF($E12=0,"",$AD12-$AF12) -> 0.0625 | AH12: =IF($E12=0,"",$AE12-$AF12) -> 0.0625 | AI12: =IF($E12=0,"",$E12/STIG_Metrics!N12) -> 2.7 | AJ12: =IF($E12=0,"",$E12/STIG_Metrics!O12) -> 2.7 | AK12: =IF($E12=0,"",$E12/STIG_Metrics!P12) -> 2.7 | AL12: =IF($E12=0,"",$E12/STIG_Metrics!Q12) -> 1.2 | AN12: Manual Review | AO12: =$Y$7 -> 14554361 | AP12: =$Y$7*2 -> 29108722 | AQ12: =$Y$7*3 -> 43663082 | AR12: =$Y$7*4 -> 58217443 | AT12: DISA SCAP | AU12: =$AO$12-$AO$13 -> 11969483 | AV12: =($AO$12-$AO$13)*2 -> 23938967 | AW12: =($AO$12-$AO$13)*3 -> 35908450 | AX12: =($AO$12-$AO$13)*4 -> 47877934
D13: =(STIG_Metrics!A13) -> Active Directory Forest | E13: 1 | G13: =IF(E13=0,"",(AG13*24)*4) -> 0.9 | H13: =IF(E13=0,"",PRODUCT($G13,$E$7)) -> 113.4 | I13: =IF(E13=0,"",(AH13*24)*4) -> 0.9 | J13: =IF(E13=0,"",PRODUCT($I13,$E$7)) -> 113.4 | K13: =IF($E13=0,"",(STIG_Metrics!E13)*$E13) -> 7 | L13: =IF($E13=0,"",(STIG_Metrics!F13)*$E13) -> 0 | M13: =IF($E13=0,"",(STIG_Metrics!G13)*$E13) -> 0 | N13: =IF($E13=0,"",(STIG_Metrics!H13)*$E13) -> 3 | O13: =IF($E13=0,"",(STIG_Metrics!E13-STIG_Metrics!F13)*$E13) -> 7 | P13: =IF($E13=0,"",(STIG_Metrics!E13-STIG_Metrics!G13)*$E13) -> 7 | Q13: =IF($E13=0,"",(STIG_Metrics!E13-STIG_Metrics!H13)*$E13) -> 4 | R13: =IF($E13=0,"",FLOOR($AC13*3,1)&" Days"&TEXT(SUM($AC13-TIME(8,0,0)*FLOOR($AC13*3,1))," h")&" Hrs") -> 0 Days 0 Hrs | S13: =IF($E13=0,"",FLOOR($AD13*3,1)&" Days"&TEXT(SUM($AD13-TIME(8,0,0)*FLOOR($AD13*3,1))," h")&" Hrs") -> 0 Days 0 Hrs | T13: =IF($E13=0,"",FLOOR($AE13*3,1)&" Days"&TEXT(SUM($AE13-TIME(8,0,0)*FLOOR($AE13*3,1))," h")&" Hrs") -> 0 Days 0 Hrs | U13: =IF($E13=0,"",FLOOR($AF13*3,1)& " Days"&TEXT(SUM($AF13-TIME(8,0,0)*FLOOR($AF13*3,1))," h") & " Hrs") -> 0 Days 0 Hrs | V13: =IF($E13=0,"",STIG_Metrics!R13) -> 0 | W13: =IF($E13=0,"",STIG_Metrics!S13) -> 0 | X13: =IF($E13=0,"",STIG_Metrics!T13) -> 0.75 | Y13: =IF($E13=0,"",((K13*$E$8/60)*$E$7)) -> 66.15 | Z13: =IF($E13=0,"",((O13*$E$8/60)*$E$7)) -> 66.15 | AA13: =IF($E13=0,"",((P13*$E$8/60)*$E$7)) -> 66.15 | AB13: =IF($E13=0,"",((Q13*$E$8/60)*$E$7)) -> 37.8 | AC13: =IF($E13=0,"",IF(STIG_Metrics!N13=60,0,($E13/STIG_Metrics!N13)/24)) -> 0.021875 | AD13: =IF($E13=0,"",IF(STIG_Metrics!O13=60,0,($E13/STIG_Metrics!O13)/24)) -> 0.021875 | AE13: =IF($E13=0,"",IF(STIG_Metrics!P13=60,0,($E13/STIG_Metrics!P13)/24)) -> 0.021875 | AF13: =IF($E13=0,"",IF(STIG_Metrics!Q13=60,0,($E13/STIG_Metrics!Q13)/24)) -> 0.0125 | AG13: =IF($E13=0,"",$AD13-$AF13) -> 0.009375 | AH13: =IF($E13=0,"",$AE13-$AF13) -> 0.009375 | AI13: =IF($E13=0,"",$E13/STIG_Metrics!N13) -> 0.525 | AJ13: =IF($E13=0,"",$E13/STIG_Metrics!O13) -> 0.525 | AK13: =IF($E13=0,"",$E13/STIG_Metrics!P13) -> 0.525 | AL13: =IF($E13=0,"",$E13/STIG_Metrics!Q13) -> 0.3 | AN13: DISA SCAP | AO13: =$Z$7 -> 2584877.4 | AP13: =$Z$7*2 -> 5169754.8 | AQ13: =$Z$7*3 -> 7754632.2 | AR13: =$Z$7*4 -> 10339510 | AT13: NIWC Enhanced SCAP | AU13: =$AO$12-$AO$14 -> 12811563 | AV13: =($AO$12-$AO$14)*2 -> 25623127 | AW13: =($AO$12-$AO$14)*3 -> 38434690 | AX13: =($AO$12-$AO$14)*4 -> 51246254
D14: =(STIG_Metrics!A14) -> Adobe Acrobat Pro XI | E14: 0 | G14: =IF(E14=0,"",(AG14*24)*4) | H14: =IF(E14=0,"",PRODUCT($G14,$E$7)) | I14: =IF(E14=0,"",(AH14*24)*4) | J14: =IF(E14=0,"",PRODUCT($I14,$E$7)) | K14: =IF($E14=0,"",(STIG_Metrics!E14)*$E14) | L14: =IF($E14=0,"",(STIG_Metrics!F14)*$E14) | M14: =IF($E14=0,"",(STIG_Metrics!G14)*$E14) | N14: =IF($E14=0,"",(STIG_Metrics!H14)*$E14) | O14: =IF($E14=0,"",(STIG_Metrics!E14-STIG_Metrics!F14)*$E14) | P14: =IF($E14=0,"",(STIG_Metrics!E14-STIG_Metrics!G14)*$E14) | Q14: =IF($E14=0,"",(STIG_Metrics!E14-STIG_Metrics!H14)*$E14) | R14: =IF($E14=0,"",FLOOR($AC14*3,1)&" Days"&TEXT(SUM($AC14-TIME(8,0,0)*FLOOR($AC14*3,1))," h")&" Hrs") | S14: =IF($E14=0,"",FLOOR($AD14*3,1)&" Days"&TEXT(SUM($AD14-TIME(8,0,0)*FLOOR($AD14*3,1))," h")&" Hrs") | T14: =IF($E14=0,"",FLOOR($AE14*3,1)&" Days"&TEXT(SUM($AE14-TIME(8,0,0)*FLOOR($AE14*3,1))," h")&" Hrs") | U14: =IF($E14=0,"",FLOOR($AF14*3,1)& " Days"&TEXT(SUM($AF14-TIME(8,0,0)*FLOOR($AF14*3,1))," h") & " Hrs") | V14: =IF($E14=0,"",STIG_Metrics!R14) | W14: =IF($E14=0,"",STIG_Metrics!S14) | X14: =IF($E14=0,"",STIG_Metrics!T14) | Y14: =IF($E14=0,"",((K14*$E$8/60)*$E$7)) | Z14: =IF($E14=0,"",((O14*$E$8/60)*$E$7)) | AA14: =IF($E14=0,"",((P14*$E$8/60)*$E$7)) | AB14: =IF($E14=0,"",((Q14*$E$8/60)*$E$7)) | AC14: =IF($E14=0,"",IF(STIG_Metrics!N14=60,0,($E14/STIG_Metrics!N14)/24)) | AD14: =IF($E14=0,"",IF(STIG_Metrics!O14=60,0,($E14/STIG_Metrics!O14)/24)) | AE14: =IF($E14=0,"",IF(STIG_Metrics!P14=60,0,($E14/STIG_Metrics!P14)/24)) | AF14: =IF($E14=0,"",IF(STIG_Metrics!Q14=60,0,($E14/STIG_Metrics!Q14)/24)) | AG14: =IF($E14=0,"",$AD14-$AF14) | AH14: =IF($E14=0,"",$AE14-$AF14) | AI14: =IF($E14=0,"",$E14/STIG_Metrics!N14) | AJ14: =IF($E14=0,"",$E14/STIG_Metrics!O14) | AK14: =IF($E14=0,"",$E14/STIG_Metrics!P14) | AL14: =IF($E14=0,"",$E14/STIG_Metrics!Q14) | AN14: NIWC Enhanced SCAP | AO14: =$AA$7 -> 1742797.4 | AP14: =$AA$7*2 -> 3485594.7 | AQ14: =$AA$7*3 -> 5228392.1 | AR14: =$AA$7*4 -> 6971189.4 | AT14: Evaluate-STIG | AU14: =$AO$12-$AO$15 -> 14236453 | AV14: =($AO$12-$AO$15)*2 -> 28472907 | AW14: =($AO$12-$AO$15)*3 -> 42709360 | AX14: =($AO$12-$AO$15)*4 -> 56945813
D15: =(STIG_Metrics!A15) -> Adobe Acrobat Professional DC Classic Track | E15: 14 | G15: =IF(E15=0,"",(AG15*24)*4) -> 96.6 | H15: =IF(E15=0,"",PRODUCT($G15,$E$7)) -> 12171.6 | I15: =IF(E15=0,"",(AH15*24)*4) -> 96.6 | J15: =IF(E15=0,"",PRODUCT($I15,$E$7)) -> 12171.6 | K15: =IF($E15=0,"",(STIG_Metrics!E15)*$E15) -> 322 | L15: =IF($E15=0,"",(STIG_Metrics!F15)*$E15) -> 0 | M15: =IF($E15=0,"",(STIG_Metrics!G15)*$E15) -> 0 | N15: =IF($E15=0,"",(STIG_Metrics!H15)*$E15) -> 322 | O15: =IF($E15=0,"",(STIG_Metrics!E15-STIG_Metrics!F15)*$E15) -> 322 | P15: =IF($E15=0,"",(STIG_Metrics!E15-STIG_Metrics!G15)*$E15) -> 322 | Q15: =IF($E15=0,"",(STIG_Metrics!E15-STIG_Metrics!H15)*$E15) -> 0 | R15: =IF($E15=0,"",FLOOR($AC15*3,1)&" Days"&TEXT(SUM($AC15-TIME(8,0,0)*FLOOR($AC15*3,1))," h")&" Hrs") -> 3 Days 0 Hrs | S15: =IF($E15=0,"",FLOOR($AD15*3,1)&" Days"&TEXT(SUM($AD15-TIME(8,0,0)*FLOOR($AD15*3,1))," h")&" Hrs") -> 3 Days 0 Hrs | T15: =IF($E15=0,"",FLOOR($AE15*3,1)&" Days"&TEXT(SUM($AE15-TIME(8,0,0)*FLOOR($AE15*3,1))," h")&" Hrs") -> 3 Days 0 Hrs | U15: =IF($E15=0,"",FLOOR($AF15*3,1)& " Days"&TEXT(SUM($AF15-TIME(8,0,0)*FLOOR($AF15*3,1))," h") & " Hrs") -> 0 Days 0 Hrs | V15: =IF($E15=0,"",STIG_Metrics!R15) -> 0 | W15: =IF($E15=0,"",STIG_Metrics!S15) -> 0 | X15: =IF($E15=0,"",STIG_Metrics!T15) -> 102.5 | Y15: =IF($E15=0,"",((K15*$E$8/60)*$E$7)) -> 3042.9 | Z15: =IF($E15=0,"",((O15*$E$8/60)*$E$7)) -> 3042.9 | AA15: =IF($E15=0,"",((P15*$E$8/60)*$E$7)) -> 3042.9 | AB15: =IF($E15=0,"",((Q15*$E$8/60)*$E$7)) -> 0 | AC15: =IF($E15=0,"",IF(STIG_Metrics!N15=60,0,($E15/STIG_Metrics!N15)/24)) -> 1.00625 | AD15: =IF($E15=0,"",IF(STIG_Metrics!O15=60,0,($E15/STIG_Metrics!O15)/24)) -> 1.00625 | AE15: =IF($E15=0,"",IF(STIG_Metrics!P15=60,0,($E15/STIG_Metrics!P15)/24)) -> 1.00625 | AF15: =IF($E15=0,"",IF(STIG_Metrics!Q15=60,0,($E15/STIG_Metrics!Q15)/24)) -> 0 | AG15: =IF($E15=0,"",$AD15-$AF15) -> 1.00625 | AH15: =IF($E15=0,"",$AE15-$AF15) -> 1.00625 | AI15: =IF($E15=0,"",$E15/STIG_Metrics!N15) -> 24.15 | AJ15: =IF($E15=0,"",$E15/STIG_Metrics!O15) -> 24.15 | AK15: =IF($E15=0,"",$E15/STIG_Metrics!P15) -> 24.15 | AL15: =IF($E15=0,"",$E15/STIG_Metrics!Q15) -> 0.23333333 | AN15: Evaluate-STIG | AO15: =$AB$7 -> 317907.45 | AP15: =$AB$7*2 -> 635814.9 | AQ15: =$AB$7*3 -> 953722.35 | AR15: =$AB$7*4 -> 1271629.8 | AT15: Evaluate-STIG over DISA SCAP | AU15: =AU14-AU12 -> 2266970 | AV15: =AV14-AV12 -> 4533939.9 | AW15: =AW14-AW12 -> 6800909.9 | AX15: =AX14-AX12 -> 9067879.8
D16: =(STIG_Metrics!A16) -> Adobe Acrobat Professional DC Continuous Track | E16: 165 | G16: =IF(E16=0,"",(AG16*24)*4) -> 1089 | H16: =IF(E16=0,"",PRODUCT($G16,$E$7)) -> 137214 | I16: =IF(E16=0,"",(AH16*24)*4) -> 1089 | J16: =IF(E16=0,"",PRODUCT($I16,$E$7)) -> 137214 | K16: =IF($E16=0,"",(STIG_Metrics!E16)*$E16) -> 3795 | L16: =IF($E16=0,"",(STIG_Metrics!F16)*$E16) -> 0 | M16: =IF($E16=0,"",(STIG_Metrics!G16)*$E16) -> 0 | N16: =IF($E16=0,"",(STIG_Metrics!H16)*$E16) -> 3630 | O16: =IF($E16=0,"",(STIG_Metrics!E16-STIG_Metrics!F16)*$E16) -> 3795 | P16: =IF($E16=0,"",(STIG_Metrics!E16-STIG_Metrics!G16)*$E16) -> 3795 | Q16: =IF($E16=0,"",(STIG_Metrics!E16-STIG_Metrics!H16)*$E16) -> 165 | R16: =IF($E16=0,"",FLOOR($AC16*3,1)&" Days"&TEXT(SUM($AC16-TIME(8,0,0)*FLOOR($AC16*3,1))," h")&" Hrs") -> 35 Days 4 Hrs | S16: =IF($E16=0,"",FLOOR($AD16*3,1)&" Days"&TEXT(SUM($AD16-TIME(8,0,0)*FLOOR($AD16*3,1))," h")&" Hrs") -> 35 Days 4 Hrs | T16: =IF($E16=0,"",FLOOR($AE16*3,1)&" Days"&TEXT(SUM($AE16-TIME(8,0,0)*FLOOR($AE16*3,1))," h")&" Hrs") -> 35 Days 4 Hrs | U16: =IF($E16=0,"",FLOOR($AF16*3,1)& " Days"&TEXT(SUM($AF16-TIME(8,0,0)*FLOOR($AF16*3,1))," h") & " Hrs") -> 1 Days 4 Hrs | V16: =IF($E16=0,"",STIG_Metrics!R16) -> 0 | W16: =IF($E16=0,"",STIG_Metrics!S16) -> 0 | X16: =IF($E16=0,"",STIG_Metrics!T16) -> 22 | Y16: =IF($E16=0,"",((K16*$E$8/60)*$E$7)) -> 35862.75 | Z16: =IF($E16=0,"",((O16*$E$8/60)*$E$7)) -> 35862.75 | AA16: =IF($E16=0,"",((P16*$E$8/60)*$E$7)) -> 35862.75 | AB16: =IF($E16=0,"",((Q16*$E$8/60)*$E$7)) -> 1559.25 | AC16: =IF($E16=0,"",IF(STIG_Metrics!N16=60,0,($E16/STIG_Metrics!N16)/24)) -> 11.859375 | AD16: =IF($E16=0,"",IF(STIG_Metrics!O16=60,0,($E16/STIG_Metrics!O16)/24)) -> 11.859375 | AE16: =IF($E16=0,"",IF(STIG_Metrics!P16=60,0,($E16/STIG_Metrics!P16)/24)) -> 11.859375 | AF16: =IF($E16=0,"",IF(STIG_Metrics!Q16=60,0,($E16/STIG_Metrics!Q16)/24)) -> 0.515625 | AG16: =IF($E16=0,"",$AD16-$AF16) -> 11.34375 | AH16: =IF($E16=0,"",$AE16-$AF16) -> 11.34375 | AI16: =IF($E16=0,"",$E16/STIG_Metrics!N16) -> 284.625 | AJ16: =IF($E16=0,"",$E16/STIG_Metrics!O16) -> 284.625 | AK16: =IF($E16=0,"",$E16/STIG_Metrics!P16) -> 284.625 | AL16: =IF($E16=0,"",$E16/STIG_Metrics!Q16) -> 12.375 | AT16: Evaluate-STIG over NIWC SCAP | AU16: =AU14-AU13 -> 1424889.9 | AV16: =AV14-AV13 -> 2849779.8 | AW16: =AW14-AW13 -> 4274669.7 | AX16: =AX14-AX13 -> 5699559.6
D17: =(STIG_Metrics!A17) -> Adobe Acrobat Reader DC Classic Track | E17: 0 | G17: =IF(E17=0,"",(AG17*24)*4) | H17: =IF(E17=0,"",PRODUCT($G17,$E$7)) | I17: =IF(E17=0,"",(AH17*24)*4) | J17: =IF(E17=0,"",PRODUCT($I17,$E$7)) | K17: =IF($E17=0,"",(STIG_Metrics!E17)*$E17) | L17: =IF($E17=0,"",(STIG_Metrics!F17)*$E17) | M17: =IF($E17=0,"",(STIG_Metrics!G17)*$E17) | N17: =IF($E17=0,"",(STIG_Metrics!H17)*$E17) | O17: =IF($E17=0,"",(STIG_Metrics!E17-STIG_Metrics!F17)*$E17) | P17: =IF($E17=0,"",(STIG_Metrics!E17-STIG_Metrics!G17)*$E17) | Q17: =IF($E17=0,"",(STIG_Metrics!E17-STIG_Metrics!H17)*$E17) | R17: =IF($E17=0,"",FLOOR($AC17*3,1)&" Days"&TEXT(SUM($AC17-TIME(8,0,0)*FLOOR($AC17*3,1))," h")&" Hrs") | S17: =IF($E17=0,"",FLOOR($AD17*3,1)&" Days"&TEXT(SUM($AD17-TIME(8,0,0)*FLOOR($AD17*3,1))," h")&" Hrs") | T17: =IF($E17=0,"",FLOOR($AE17*3,1)&" Days"&TEXT(SUM($AE17-TIME(8,0,0)*FLOOR($AE17*3,1))," h")&" Hrs") | U17: =IF($E17=0,"",FLOOR($AF17*3,1)& " Days"&TEXT(SUM($AF17-TIME(8,0,0)*FLOOR($AF17*3,1))," h") & " Hrs") | V17: =IF($E17=0,"",STIG_Metrics!R17) | W17: =IF($E17=0,"",STIG_Metrics!S17) | X17: =IF($E17=0,"",STIG_Metrics!T17) | Y17: =IF($E17=0,"",((K17*$E$8/60)*$E$7)) | Z17: =IF($E17=0,"",((O17*$E$8/60)*$E$7)) | AA17: =IF($E17=0,"",((P17*$E$8/60)*$E$7)) | AB17: =IF($E17=0,"",((Q17*$E$8/60)*$E$7)) | AC17: =IF($E17=0,"",IF(STIG_Metrics!N17=60,0,($E17/STIG_Metrics!N17)/24)) | AD17: =IF($E17=0,"",IF(STIG_Metrics!O17=60,0,($E17/STIG_Metrics!O17)/24)) | AE17: =IF($E17=0,"",IF(STIG_Metrics!P17=60,0,($E17/STIG_Metrics!P17)/24)) | AF17: =IF($E17=0,"",IF(STIG_Metrics!Q17=60,0,($E17/STIG_Metrics!Q17)/24)) | AG17: =IF($E17=0,"",$AD17-$AF17) | AH17: =IF($E17=0,"",$AE17-$AF17) | AI17: =IF($E17=0,"",$E17/STIG_Metrics!N17) | AJ17: =IF($E17=0,"",$E17/STIG_Metrics!O17) | AK17: =IF($E17=0,"",$E17/STIG_Metrics!P17) | AL17: =IF($E17=0,"",$E17/STIG_Metrics!Q17)
D18: =(STIG_Metrics!A18) -> Adobe Acrobat Reader DC Continuous Track | E18: 1400 | G18: =IF(E18=0,"",(AG18*24)*4) -> 1260 | H18: =IF(E18=0,"",PRODUCT($G18,$E$7)) -> 158760 | I18: =IF(E18=0,"",(AH18*24)*4) -> 0 | J18: =IF(E18=0,"",PRODUCT($I18,$E$7)) -> 0 | K18: =IF($E18=0,"",(STIG_Metrics!E18)*$E18) -> 36400 | L18: =IF($E18=0,"",(STIG_Metrics!F18)*$E18) -> 30800 | M18: =IF($E18=0,"",(STIG_Metrics!G18)*$E18) -> 35000 | N18: =IF($E18=0,"",(STIG_Metrics!H18)*$E18) -> 35000 | O18: =IF($E18=0,"",(STIG_Metrics!E18-STIG_Metrics!F18)*$E18) -> 5600 | P18: =IF($E18=0,"",(STIG_Metrics!E18-STIG_Metrics!G18)*$E18) -> 1400 | Q18: =IF($E18=0,"",(STIG_Metrics!E18-STIG_Metrics!H18)*$E18) -> 1400 | R18: =IF($E18=0,"",FLOOR($AC18*3,1)&" Days"&TEXT(SUM($AC18-TIME(8,0,0)*FLOOR($AC18*3,1))," h")&" Hrs") -> 341 Days 2 Hrs | S18: =IF($E18=0,"",FLOOR($AD18*3,1)&" Days"&TEXT(SUM($AD18-TIME(8,0,0)*FLOOR($AD18*3,1))," h")&" Hrs") -> 52 Days 4 Hrs | T18: =IF($E18=0,"",FLOOR($AE18*3,1)&" Days"&TEXT(SUM($AE18-TIME(8,0,0)*FLOOR($AE18*3,1))," h")&" Hrs") -> 13 Days 1 Hrs | U18: =IF($E18=0,"",FLOOR($AF18*3,1)& " Days"&TEXT(SUM($AF18-TIME(8,0,0)*FLOOR($AF18*3,1))," h") & " Hrs") -> 13 Days 1 Hrs | V18: =IF($E18=0,"",STIG_Metrics!R18) -> 5.5 | W18: =IF($E18=0,"",STIG_Metrics!S18) -> 25 | X18: =IF($E18=0,"",STIG_Metrics!T18) -> 25 | Y18: =IF($E18=0,"",((K18*$E$8/60)*$E$7)) -> 343980 | Z18: =IF($E18=0,"",((O18*$E$8/60)*$E$7)) -> 52920 | AA18: =IF($E18=0,"",((P18*$E$8/60)*$E$7)) -> 13230 | AB18: =IF($E18=0,"",((Q18*$E$8/60)*$E$7)) -> 13230 | AC18: =IF($E18=0,"",IF(STIG_Metrics!N18=60,0,($E18/STIG_Metrics!N18)/24)) -> 113.75 | AD18: =IF($E18=0,"",IF(STIG_Metrics!O18=60,0,($E18/STIG_Metrics!O18)/24)) -> 17.5 | AE18: =IF($E18=0,"",IF(STIG_Metrics!P18=60,0,($E18/STIG_Metrics!P18)/24)) -> 4.375 | AF18: =IF($E18=0,"",IF(STIG_Metrics!Q18=60,0,($E18/STIG_Metrics!Q18)/24)) -> 4.375 | AG18: =IF($E18=0,"",$AD18-$AF18) -> 13.125 | AH18: =IF($E18=0,"",$AE18-$AF18) -> 0 | AI18: =IF($E18=0,"",$E18/STIG_Metrics!N18) -> 2730 | AJ18: =IF($E18=0,"",$E18/STIG_Metrics!O18) -> 420 | AK18: =IF($E18=0,"",$E18/STIG_Metrics!P18) -> 105 | AL18: =IF($E18=0,"",$E18/STIG_Metrics!Q18) -> 105
D19: =(STIG_Metrics!A19) -> Amazon Linux 2023 | E19: 0 | G19: =IF(E19=0,"",(AG19*24)*4) | H19: =IF(E19=0,"",PRODUCT($G19,$E$7)) | I19: =IF(E19=0,"",(AH19*24)*4) | J19: =IF(E19=0,"",PRODUCT($I19,$E$7)) | K19: =IF($E19=0,"",(STIG_Metrics!E19)*$E19) | L19: =IF($E19=0,"",(STIG_Metrics!F19)*$E19) | M19: =IF($E19=0,"",(STIG_Metrics!G19)*$E19) | N19: =IF($E19=0,"",(STIG_Metrics!H19)*$E19) | O19: =IF($E19=0,"",(STIG_Metrics!E19-STIG_Metrics!F19)*$E19) | P19: =IF($E19=0,"",(STIG_Metrics!E19-STIG_Metrics!G19)*$E19) | Q19: =IF($E19=0,"",(STIG_Metrics!E19-STIG_Metrics!H19)*$E19) | R19: =IF($E19=0,"",FLOOR($AC19*3,1)&" Days"&TEXT(SUM($AC19-TIME(8,0,0)*FLOOR($AC19*3,1))," h")&" Hrs") | S19: =IF($E19=0,"",FLOOR($AD19*3,1)&" Days"&TEXT(SUM($AD19-TIME(8,0,0)*FLOOR($AD19*3,1))," h")&" Hrs") | T19: =IF($E19=0,"",FLOOR($AE19*3,1)&" Days"&TEXT(SUM($AE19-TIME(8,0,0)*FLOOR($AE19*3,1))," h")&" Hrs") | U19: =IF($E19=0,"",FLOOR($AF19*3,1)& " Days"&TEXT(SUM($AF19-TIME(8,0,0)*FLOOR($AF19*3,1))," h") & " Hrs") | V19: =IF($E19=0,"",STIG_Metrics!R19) | W19: =IF($E19=0,"",STIG_Metrics!S19) | X19: =IF($E19=0,"",STIG_Metrics!T19) | Y19: =IF($E19=0,"",((K19*$E$8/60)*$E$7)) | Z19: =IF($E19=0,"",((O19*$E$8/60)*$E$7)) | AA19: =IF($E19=0,"",((P19*$E$8/60)*$E$7)) | AB19: =IF($E19=0,"",((Q19*$E$8/60)*$E$7)) | AC19: =IF($E19=0,"",IF(STIG_Metrics!N19=60,0,($E19/STIG_Metrics!N19)/24)) | AD19: =IF($E19=0,"",IF(STIG_Metrics!O19=60,0,($E19/STIG_Metrics!O19)/24)) | AE19: =IF($E19=0,"",IF(STIG_Metrics!P19=60,0,($E19/STIG_Metrics!P19)/24)) | AF19: =IF($E19=0,"",IF(STIG_Metrics!Q19=60,0,($E19/STIG_Metrics!Q19)/24)) | AG19: =IF($E19=0,"",$AD19-$AF19) | AH19: =IF($E19=0,"",$AE19-$AF19) | AI19: =IF($E19=0,"",$E19/STIG_Metrics!N19) | AJ19: =IF($E19=0,"",$E19/STIG_Metrics!O19) | AK19: =IF($E19=0,"",$E19/STIG_Metrics!P19) | AL19: =IF($E19=0,"",$E19/STIG_Metrics!Q19)
D20: =(STIG_Metrics!A20) -> Apache Server 2.4 UNIX Server | E20: 0 | G20: =IF(E20=0,"",(AG20*24)*4) | H20: =IF(E20=0,"",PRODUCT($G20,$E$7)) | I20: =IF(E20=0,"",(AH20*24)*4) | J20: =IF(E20=0,"",PRODUCT($I20,$E$7)) | K20: =IF($E20=0,"",(STIG_Metrics!E20)*$E20) | L20: =IF($E20=0,"",(STIG_Metrics!F20)*$E20) | M20: =IF($E20=0,"",(STIG_Metrics!G20)*$E20) | N20: =IF($E20=0,"",(STIG_Metrics!H20)*$E20) | O20: =IF($E20=0,"",(STIG_Metrics!E20-STIG_Metrics!F20)*$E20) | P20: =IF($E20=0,"",(STIG_Metrics!E20-STIG_Metrics!G20)*$E20) | Q20: =IF($E20=0,"",(STIG_Metrics!E20-STIG_Metrics!H20)*$E20) | R20: =IF($E20=0,"",FLOOR($AC20*3,1)&" Days"&TEXT(SUM($AC20-TIME(8,0,0)*FLOOR($AC20*3,1))," h")&" Hrs") | S20: =IF($E20=0,"",FLOOR($AD20*3,1)&" Days"&TEXT(SUM($AD20-TIME(8,0,0)*FLOOR($AD20*3,1))," h")&" Hrs") | T20: =IF($E20=0,"",FLOOR($AE20*3,1)&" Days"&TEXT(SUM($AE20-TIME(8,0,0)*FLOOR($AE20*3,1))," h")&" Hrs") | U20: =IF($E20=0,"",FLOOR($AF20*3,1)& " Days"&TEXT(SUM($AF20-TIME(8,0,0)*FLOOR($AF20*3,1))," h") & " Hrs") | V20: =IF($E20=0,"",STIG_Metrics!R20) | W20: =IF($E20=0,"",STIG_Metrics!S20) | X20: =IF($E20=0,"",STIG_Metrics!T20) | Y20: =IF($E20=0,"",((K20*$E$8/60)*$E$7)) | Z20: =IF($E20=0,"",((O20*$E$8/60)*$E$7)) | AA20: =IF($E20=0,"",((P20*$E$8/60)*$E$7)) | AB20: =IF($E20=0,"",((Q20*$E$8/60)*$E$7)) | AC20: =IF($E20=0,"",IF(STIG_Metrics!N20=60,0,($E20/STIG_Metrics!N20)/24)) | AD20: =IF($E20=0,"",IF(STIG_Metrics!O20=60,0,($E20/STIG_Metrics!O20)/24)) | AE20: =IF($E20=0,"",IF(STIG_Metrics!P20=60,0,($E20/STIG_Metrics!P20)/24)) | AF20: =IF($E20=0,"",IF(STIG_Metrics!Q20=60,0,($E20/STIG_Metrics!Q20)/24)) | AG20: =IF($E20=0,"",$AD20-$AF20) | AH20: =IF($E20=0,"",$AE20-$AF20) | AI20: =IF($E20=0,"",$E20/STIG_Metrics!N20) | AJ20: =IF($E20=0,"",$E20/STIG_Metrics!O20) | AK20: =IF($E20=0,"",$E20/STIG_Metrics!P20) | AL20: =IF($E20=0,"",$E20/STIG_Metrics!Q20)
D21: =(STIG_Metrics!A21) -> Apache Server 2.4 UNIX Site | E21: 2 | G21: =IF(E21=0,"",(AG21*24)*4) -> 9.6 | H21: =IF(E21=0,"",PRODUCT($G21,$E$7)) -> 1209.6 | I21: =IF(E21=0,"",(AH21*24)*4) -> 9.6 | J21: =IF(E21=0,"",PRODUCT($I21,$E$7)) -> 1209.6 | K21: =IF($E21=0,"",(STIG_Metrics!E21)*$E21) -> 54 | L21: =IF($E21=0,"",(STIG_Metrics!F21)*$E21) -> 0 | M21: =IF($E21=0,"",(STIG_Metrics!G21)*$E21) -> 0 | N21: =IF($E21=0,"",(STIG_Metrics!H21)*$E21) -> 32 | O21: =IF($E21=0,"",(STIG_Metrics!E21-STIG_Metrics!F21)*$E21) -> 54 | P21: =IF($E21=0,"",(STIG_Metrics!E21-STIG_Metrics!G21)*$E21) -> 54 | Q21: =IF($E21=0,"",(STIG_Metrics!E21-STIG_Metrics!H21)*$E21) -> 22 | R21: =IF($E21=0,"",FLOOR($AC21*3,1)&" Days"&TEXT(SUM($AC21-TIME(8,0,0)*FLOOR($AC21*3,1))," h")&" Hrs") -> 0 Days 4 Hrs | S21: =IF($E21=0,"",FLOOR($AD21*3,1)&" Days"&TEXT(SUM($AD21-TIME(8,0,0)*FLOOR($AD21*3,1))," h")&" Hrs") -> 0 Days 4 Hrs | T21: =IF($E21=0,"",FLOOR($AE21*3,1)&" Days"&TEXT(SUM($AE21-TIME(8,0,0)*FLOOR($AE21*3,1))," h")&" Hrs") -> 0 Days 4 Hrs | U21: =IF($E21=0,"",FLOOR($AF21*3,1)& " Days"&TEXT(SUM($AF21-TIME(8,0,0)*FLOOR($AF21*3,1))," h") & " Hrs") -> 0 Days 1 Hrs | V21: =IF($E21=0,"",STIG_Metrics!R21) -> 0 | W21: =IF($E21=0,"",STIG_Metrics!S21) -> 0 | X21: =IF($E21=0,"",STIG_Metrics!T21) -> 1.4545455 | Y21: =IF($E21=0,"",((K21*$E$8/60)*$E$7)) -> 510.3 | Z21: =IF($E21=0,"",((O21*$E$8/60)*$E$7)) -> 510.3 | AA21: =IF($E21=0,"",((P21*$E$8/60)*$E$7)) -> 510.3 | AB21: =IF($E21=0,"",((Q21*$E$8/60)*$E$7)) -> 207.9 | AC21: =IF($E21=0,"",IF(STIG_Metrics!N21=60,0,($E21/STIG_Metrics!N21)/24)) -> 0.16875 | AD21: =IF($E21=0,"",IF(STIG_Metrics!O21=60,0,($E21/STIG_Metrics!O21)/24)) -> 0.16875 | AE21: =IF($E21=0,"",IF(STIG_Metrics!P21=60,0,($E21/STIG_Metrics!P21)/24)) -> 0.16875 | AF21: =IF($E21=0,"",IF(STIG_Metrics!Q21=60,0,($E21/STIG_Metrics!Q21)/24)) -> 0.06875 | AG21: =IF($E21=0,"",$AD21-$AF21) -> 0.1 | AH21: =IF($E21=0,"",$AE21-$AF21) -> 0.1 | AI21: =IF($E21=0,"",$E21/STIG_Metrics!N21) -> 4.05 | AJ21: =IF($E21=0,"",$E21/STIG_Metrics!O21) -> 4.05 | AK21: =IF($E21=0,"",$E21/STIG_Metrics!P21) -> 4.05 | AL21: =IF($E21=0,"",$E21/STIG_Metrics!Q21) -> 1.65
D22: =(STIG_Metrics!A22) -> Apache Server 2.4 Windows Server | E22: 2 | G22: =IF(E22=0,"",(AG22*24)*4) -> 15 | H22: =IF(E22=0,"",PRODUCT($G22,$E$7)) -> 1890 | I22: =IF(E22=0,"",(AH22*24)*4) -> 15 | J22: =IF(E22=0,"",PRODUCT($I22,$E$7)) -> 1890 | K22: =IF($E22=0,"",(STIG_Metrics!E22)*$E22) -> 108 | L22: =IF($E22=0,"",(STIG_Metrics!F22)*$E22) -> 0 | M22: =IF($E22=0,"",(STIG_Metrics!G22)*$E22) -> 0 | N22: =IF($E22=0,"",(STIG_Metrics!H22)*$E22) -> 50 | O22: =IF($E22=0,"",(STIG_Metrics!E22-STIG_Metrics!F22)*$E22) -> 108 | P22: =IF($E22=0,"",(STIG_Metrics!E22-STIG_Metrics!G22)*$E22) -> 108 | Q22: =IF($E22=0,"",(STIG_Metrics!E22-STIG_Metrics!H22)*$E22) -> 58 | R22: =IF($E22=0,"",FLOOR($AC22*3,1)&" Days"&TEXT(SUM($AC22-TIME(8,0,0)*FLOOR($AC22*3,1))," h")&" Hrs") -> 1 Days 0 Hrs | S22: =IF($E22=0,"",FLOOR($AD22*3,1)&" Days"&TEXT(SUM($AD22-TIME(8,0,0)*FLOOR($AD22*3,1))," h")&" Hrs") -> 1 Days 0 Hrs | T22: =IF($E22=0,"",FLOOR($AE22*3,1)&" Days"&TEXT(SUM($AE22-TIME(8,0,0)*FLOOR($AE22*3,1))," h")&" Hrs") -> 1 Days 0 Hrs | U22: =IF($E22=0,"",FLOOR($AF22*3,1)& " Days"&TEXT(SUM($AF22-TIME(8,0,0)*FLOOR($AF22*3,1))," h") & " Hrs") -> 0 Days 4 Hrs | V22: =IF($E22=0,"",STIG_Metrics!R22) -> 0 | W22: =IF($E22=0,"",STIG_Metrics!S22) -> 0 | X22: =IF($E22=0,"",STIG_Metrics!T22) -> 0.86206897 | Y22: =IF($E22=0,"",((K22*$E$8/60)*$E$7)) -> 1020.6 | Z22: =IF($E22=0,"",((O22*$E$8/60)*$E$7)) -> 1020.6 | AA22: =IF($E22=0,"",((P22*$E$8/60)*$E$7)) -> 1020.6 | AB22: =IF($E22=0,"",((Q22*$E$8/60)*$E$7)) -> 548.1 | AC22: =IF($E22=0,"",IF(STIG_Metrics!N22=60,0,($E22/STIG_Metrics!N22)/24)) -> 0.3375 | AD22: =IF($E22=0,"",IF(STIG_Metrics!O22=60,0,($E22/STIG_Metrics!O22)/24)) -> 0.3375 | AE22: =IF($E22=0,"",IF(STIG_Metrics!P22=60,0,($E22/STIG_Metrics!P22)/24)) -> 0.3375 | AF22: =IF($E22=0,"",IF(STIG_Metrics!Q22=60,0,($E22/STIG_Metrics!Q22)/24)) -> 0.18125 | AG22: =IF($E22=0,"",$AD22-$AF22) -> 0.15625 | AH22: =IF($E22=0,"",$AE22-$AF22) -> 0.15625 | AI22: =IF($E22=0,"",$E22/STIG_Metrics!N22) -> 8.1 | AJ22: =IF($E22=0,"",$E22/STIG_Metrics!O22) -> 8.1 | AK22: =IF($E22=0,"",$E22/STIG_Metrics!P22) -> 8.1 | AL22: =IF($E22=0,"",$E22/STIG_Metrics!Q22) -> 4.35
D23: =(STIG_Metrics!A23) -> Apache Server 2.4 Windows Site | E23: 2 | G23: =IF(E23=0,"",(AG23*24)*4) -> 12.6 | H23: =IF(E23=0,"",PRODUCT($G23,$E$7)) -> 1587.6 | I23: =IF(E23=0,"",(AH23*24)*4) -> 12.6 | J23: =IF(E23=0,"",PRODUCT($I23,$E$7)) -> 1587.6 | K23: =IF($E23=0,"",(STIG_Metrics!E23)*$E23) -> 72 | L23: =IF($E23=0,"",(STIG_Metrics!F23)*$E23) -> 0 | M23: =IF($E23=0,"",(STIG_Metrics!G23)*$E23) -> 0 | N23: =IF($E23=0,"",(STIG_Metrics!H23)*$E23) -> 42 | O23: =IF($E23=0,"",(STIG_Metrics!E23-STIG_Metrics!F23)*$E23) -> 72 | P23: =IF($E23=0,"",(STIG_Metrics!E23-STIG_Metrics!G23)*$E23) -> 72 | Q23: =IF($E23=0,"",(STIG_Metrics!E23-STIG_Metrics!H23)*$E23) -> 30 | R23: =IF($E23=0,"",FLOOR($AC23*3,1)&" Days"&TEXT(SUM($AC23-TIME(8,0,0)*FLOOR($AC23*3,1))," h")&" Hrs") -> 0 Days 5 Hrs | S23: =IF($E23=0,"",FLOOR($AD23*3,1)&" Days"&TEXT(SUM($AD23-TIME(8,0,0)*FLOOR($AD23*3,1))," h")&" Hrs") -> 0 Days 5 Hrs | T23: =IF($E23=0,"",FLOOR($AE23*3,1)&" Days"&TEXT(SUM($AE23-TIME(8,0,0)*FLOOR($AE23*3,1))," h")&" Hrs") -> 0 Days 5 Hrs | U23: =IF($E23=0,"",FLOOR($AF23*3,1)& " Days"&TEXT(SUM($AF23-TIME(8,0,0)*FLOOR($AF23*3,1))," h") & " Hrs") -> 0 Days 2 Hrs | V23: =IF($E23=0,"",STIG_Metrics!R23) -> 0 | W23: =IF($E23=0,"",STIG_Metrics!S23) -> 0 | X23: =IF($E23=0,"",STIG_Metrics!T23) -> 1.4 | Y23: =IF($E23=0,"",((K23*$E$8/60)*$E$7)) -> 680.4 | Z23: =IF($E23=0,"",((O23*$E$8/60)*$E$7)) -> 680.4 | AA23: =IF($E23=0,"",((P23*$E$8/60)*$E$7)) -> 680.4 | AB23: =IF($E23=0,"",((Q23*$E$8/60)*$E$7)) -> 283.5 | AC23: =IF($E23=0,"",IF(STIG_Metrics!N23=60,0,($E23/STIG_Metrics!N23)/24)) -> 0.225 | AD23: =IF($E23=0,"",IF(STIG_Metrics!O23=60,0,($E23/STIG_Metrics!O23)/24)) -> 0.225 | AE23: =IF($E23=0,"",IF(STIG_Metrics!P23=60,0,($E23/STIG_Metrics!P23)/24)) -> 0.225 | AF23: =IF($E23=0,"",IF(STIG_Metrics!Q23=60,0,($E23/STIG_Metrics!Q23)/24)) -> 0.09375 | AG23: =IF($E23=0,"",$AD23-$AF23) -> 0.13125 | AH23: =IF($E23=0,"",$AE23-$AF23) -> 0.13125 | AI23: =IF($E23=0,"",$E23/STIG_Metrics!N23) -> 5.4 | AJ23: =IF($E23=0,"",$E23/STIG_Metrics!O23) -> 5.4 | AK23: =IF($E23=0,"",$E23/STIG_Metrics!P23) -> 5.4 | AL23: =IF($E23=0,"",$E23/STIG_Metrics!Q23) -> 2.25
D24: =(STIG_Metrics!A24) -> Apache Tomcat Application Server 9 | E24: 0 | G24: =IF(E24=0,"",(AG24*24)*4) | H24: =IF(E24=0,"",PRODUCT($G24,$E$7)) | I24: =IF(E24=0,"",(AH24*24)*4) | J24: =IF(E24=0,"",PRODUCT($I24,$E$7)) | K24: =IF($E24=0,"",(STIG_Metrics!E24)*$E24) | L24: =IF($E24=0,"",(STIG_Metrics!F24)*$E24) | M24: =IF($E24=0,"",(STIG_Metrics!G24)*$E24) | N24: =IF($E24=0,"",(STIG_Metrics!H24)*$E24) | O24: =IF($E24=0,"",(STIG_Metrics!E24-STIG_Metrics!F24)*$E24) | P24: =IF($E24=0,"",(STIG_Metrics!E24-STIG_Metrics!G24)*$E24) | Q24: =IF($E24=0,"",(STIG_Metrics!E24-STIG_Metrics!H24)*$E24) | R24: =IF($E24=0,"",FLOOR($AC24*3,1)&" Days"&TEXT(SUM($AC24-TIME(8,0,0)*FLOOR($AC24*3,1))," h")&" Hrs") | S24: =IF($E24=0,"",FLOOR($AD24*3,1)&" Days"&TEXT(SUM($AD24-TIME(8,0,0)*FLOOR($AD24*3,1))," h")&" Hrs") | T24: =IF($E24=0,"",FLOOR($AE24*3,1)&" Days"&TEXT(SUM($AE24-TIME(8,0,0)*FLOOR($AE24*3,1))," h")&" Hrs") | U24: =IF($E24=0,"",FLOOR($AF24*3,1)& " Days"&TEXT(SUM($AF24-TIME(8,0,0)*FLOOR($AF24*3,1))," h") & " Hrs") | V24: =IF($E24=0,"",STIG_Metrics!R24) | W24: =IF($E24=0,"",STIG_Metrics!S24) | X24: =IF($E24=0,"",STIG_Metrics!T24) | Y24: =IF($E24=0,"",((K24*$E$8/60)*$E$7)) | Z24: =IF($E24=0,"",((O24*$E$8/60)*$E$7)) | AA24: =IF($E24=0,"",((P24*$E$8/60)*$E$7)) | AB24: =IF($E24=0,"",((Q24*$E$8/60)*$E$7)) | AC24: =IF($E24=0,"",IF(STIG_Metrics!N24=60,0,($E24/STIG_Metrics!N24)/24)) | AD24: =IF($E24=0,"",IF(STIG_Metrics!O24=60,0,($E24/STIG_Metrics!O24)/24)) | AE24: =IF($E24=0,"",IF(STIG_Metrics!P24=60,0,($E24/STIG_Metrics!P24)/24)) | AF24: =IF($E24=0,"",IF(STIG_Metrics!Q24=60,0,($E24/STIG_Metrics!Q24)/24)) | AG24: =IF($E24=0,"",$AD24-$AF24) | AH24: =IF($E24=0,"",$AE24-$AF24) | AI24: =IF($E24=0,"",$E24/STIG_Metrics!N24) | AJ24: =IF($E24=0,"",$E24/STIG_Metrics!O24) | AK24: =IF($E24=0,"",$E24/STIG_Metrics!P24) | AL24: =IF($E24=0,"",$E24/STIG_Metrics!Q24)
D25: =(STIG_Metrics!A25) -> ArcGIS for Server 10.3 | E25: 0 | G25: =IF(E25=0,"",(AG25*24)*4) | H25: =IF(E25=0,"",PRODUCT($G25,$E$7)) | I25: =IF(E25=0,"",(AH25*24)*4) | J25: =IF(E25=0,"",PRODUCT($I25,$E$7)) | K25: =IF($E25=0,"",(STIG_Metrics!E25)*$E25) | L25: =IF($E25=0,"",(STIG_Metrics!F25)*$E25) | M25: =IF($E25=0,"",(STIG_Metrics!G25)*$E25) | N25: =IF($E25=0,"",(STIG_Metrics!H25)*$E25) | O25: =IF($E25=0,"",(STIG_Metrics!E25-STIG_Metrics!F25)*$E25) | P25: =IF($E25=0,"",(STIG_Metrics!E25-STIG_Metrics!G25)*$E25) | Q25: =IF($E25=0,"",(STIG_Metrics!E25-STIG_Metrics!H25)*$E25) | R25: =IF($E25=0,"",FLOOR($AC25*3,1)&" Days"&TEXT(SUM($AC25-TIME(8,0,0)*FLOOR($AC25*3,1))," h")&" Hrs") | S25: =IF($E25=0,"",FLOOR($AD25*3,1)&" Days"&TEXT(SUM($AD25-TIME(8,0,0)*FLOOR($AD25*3,1))," h")&" Hrs") | T25: =IF($E25=0,"",FLOOR($AE25*3,1)&" Days"&TEXT(SUM($AE25-TIME(8,0,0)*FLOOR($AE25*3,1))," h")&" Hrs") | U25: =IF($E25=0,"",FLOOR($AF25*3,1)& " Days"&TEXT(SUM($AF25-TIME(8,0,0)*FLOOR($AF25*3,1))," h") & " Hrs") | V25: =IF($E25=0,"",STIG_Metrics!R25) | W25: =IF($E25=0,"",STIG_Metrics!S25) | X25: =IF($E25=0,"",STIG_Metrics!T25) | Y25: =IF($E25=0,"",((K25*$E$8/60)*$E$7)) | Z25: =IF($E25=0,"",((O25*$E$8/60)*$E$7)) | AA25: =IF($E25=0,"",((P25*$E$8/60)*$E$7)) | AB25: =IF($E25=0,"",((Q25*$E$8/60)*$E$7)) | AC25: =IF($E25=0,"",IF(STIG_Metrics!N25=60,0,($E25/STIG_Metrics!N25)/24)) | AD25: =IF($E25=0,"",IF(STIG_Metrics!O25=60,0,($E25/STIG_Metrics!O25)/24)) | AE25: =IF($E25=0,"",IF(STIG_Metrics!P25=60,0,($E25/STIG_Metrics!P25)/24)) | AF25: =IF($E25=0,"",IF(STIG_Metrics!Q25=60,0,($E25/STIG_Metrics!Q25)/24)) | AG25: =IF($E25=0,"",$AD25-$AF25) | AH25: =IF($E25=0,"",$AE25-$AF25) | AI25: =IF($E25=0,"",$E25/STIG_Metrics!N25) | AJ25: =IF($E25=0,"",$E25/STIG_Metrics!O25) | AK25: =IF($E25=0,"",$E25/STIG_Metrics!P25) | AL25: =IF($E25=0,"",$E25/STIG_Metrics!Q25)
D26: =(STIG_Metrics!A26) -> Canonical Ubuntu 16.04 LTS | E26: 0 | G26: =IF(E26=0,"",(AG26*24)*4) | H26: =IF(E26=0,"",PRODUCT($G26,$E$7)) | I26: =IF(E26=0,"",(AH26*24)*4) | J26: =IF(E26=0,"",PRODUCT($I26,$E$7)) | K26: =IF($E26=0,"",(STIG_Metrics!E26)*$E26) | L26: =IF($E26=0,"",(STIG_Metrics!F26)*$E26) | M26: =IF($E26=0,"",(STIG_Metrics!G26)*$E26) | N26: =IF($E26=0,"",(STIG_Metrics!H26)*$E26) | O26: =IF($E26=0,"",(STIG_Metrics!E26-STIG_Metrics!F26)*$E26) | P26: =IF($E26=0,"",(STIG_Metrics!E26-STIG_Metrics!G26)*$E26) | Q26: =IF($E26=0,"",(STIG_Metrics!E26-STIG_Metrics!H26)*$E26) | R26: =IF($E26=0,"",FLOOR($AC26*3,1)&" Days"&TEXT(SUM($AC26-TIME(8,0,0)*FLOOR($AC26*3,1))," h")&" Hrs") | S26: =IF($E26=0,"",FLOOR($AD26*3,1)&" Days"&TEXT(SUM($AD26-TIME(8,0,0)*FLOOR($AD26*3,1))," h")&" Hrs") | T26: =IF($E26=0,"",FLOOR($AE26*3,1)&" Days"&TEXT(SUM($AE26-TIME(8,0,0)*FLOOR($AE26*3,1))," h")&" Hrs") | U26: =IF($E26=0,"",FLOOR($AF26*3,1)& " Days"&TEXT(SUM($AF26-TIME(8,0,0)*FLOOR($AF26*3,1))," h") & " Hrs") | V26: =IF($E26=0,"",STIG_Metrics!R26) | W26: =IF($E26=0,"",STIG_Metrics!S26) | X26: =IF($E26=0,"",STIG_Metrics!T26) | Y26: =IF($E26=0,"",((K26*$E$8/60)*$E$7)) | Z26: =IF($E26=0,"",((O26*$E$8/60)*$E$7)) | AA26: =IF($E26=0,"",((P26*$E$8/60)*$E$7)) | AB26: =IF($E26=0,"",((Q26*$E$8/60)*$E$7)) | AC26: =IF($E26=0,"",IF(STIG_Metrics!N26=60,0,($E26/STIG_Metrics!N26)/24)) | AD26: =IF($E26=0,"",IF(STIG_Metrics!O26=60,0,($E26/STIG_Metrics!O26)/24)) | AE26: =IF($E26=0,"",IF(STIG_Metrics!P26=60,0,($E26/STIG_Metrics!P26)/24)) | AF26: =IF($E26=0,"",IF(STIG_Metrics!Q26=60,0,($E26/STIG_Metrics!Q26)/24)) | AG26: =IF($E26=0,"",$AD26-$AF26) | AH26: =IF($E26=0,"",$AE26-$AF26) | AI26: =IF($E26=0,"",$E26/STIG_Metrics!N26) | AJ26: =IF($E26=0,"",$E26/STIG_Metrics!O26) | AK26: =IF($E26=0,"",$E26/STIG_Metrics!P26) | AL26: =IF($E26=0,"",$E26/STIG_Metrics!Q26)
D27: =(STIG_Metrics!A27) -> Canonical Ubuntu 18.04 LTS | E27: 0 | G27: =IF(E27=0,"",(AG27*24)*4) | H27: =IF(E27=0,"",PRODUCT($G27,$E$7)) | I27: =IF(E27=0,"",(AH27*24)*4) | J27: =IF(E27=0,"",PRODUCT($I27,$E$7)) | K27: =IF($E27=0,"",(STIG_Metrics!E27)*$E27) | L27: =IF($E27=0,"",(STIG_Metrics!F27)*$E27) | M27: =IF($E27=0,"",(STIG_Metrics!G27)*$E27) | N27: =IF($E27=0,"",(STIG_Metrics!H27)*$E27) | O27: =IF($E27=0,"",(STIG_Metrics!E27-STIG_Metrics!F27)*$E27) | P27: =IF($E27=0,"",(STIG_Metrics!E27-STIG_Metrics!G27)*$E27) | Q27: =IF($E27=0,"",(STIG_Metrics!E27-STIG_Metrics!H27)*$E27) | R27: =IF($E27=0,"",FLOOR($AC27*3,1)&" Days"&TEXT(SUM($AC27-TIME(8,0,0)*FLOOR($AC27*3,1))," h")&" Hrs") | S27: =IF($E27=0,"",FLOOR($AD27*3,1)&" Days"&TEXT(SUM($AD27-TIME(8,0,0)*FLOOR($AD27*3,1))," h")&" Hrs") | T27: =IF($E27=0,"",FLOOR($AE27*3,1)&" Days"&TEXT(SUM($AE27-TIME(8,0,0)*FLOOR($AE27*3,1))," h")&" Hrs") | U27: =IF($E27=0,"",FLOOR($AF27*3,1)& " Days"&TEXT(SUM($AF27-TIME(8,0,0)*FLOOR($AF27*3,1))," h") & " Hrs") | V27: =IF($E27=0,"",STIG_Metrics!R27) | W27: =IF($E27=0,"",STIG_Metrics!S27) | X27: =IF($E27=0,"",STIG_Metrics!T27) | Y27: =IF($E27=0,"",((K27*$E$8/60)*$E$7)) | Z27: =IF($E27=0,"",((O27*$E$8/60)*$E$7)) | AA27: =IF($E27=0,"",((P27*$E$8/60)*$E$7)) | AB27: =IF($E27=0,"",((Q27*$E$8/60)*$E$7)) | AC27: =IF($E27=0,"",IF(STIG_Metrics!N27=60,0,($E27/STIG_Metrics!N27)/24)) | AD27: =IF($E27=0,"",IF(STIG_Metrics!O27=60,0,($E27/STIG_Metrics!O27)/24)) | AE27: =IF($E27=0,"",IF(STIG_Metrics!P27=60,0,($E27/STIG_Metrics!P27)/24)) | AF27: =IF($E27=0,"",IF(STIG_Metrics!Q27=60,0,($E27/STIG_Metrics!Q27)/24)) | AG27: =IF($E27=0,"",$AD27-$AF27) | AH27: =IF($E27=0,"",$AE27-$AF27) | AI27: =IF($E27=0,"",$E27/STIG_Metrics!N27) | AJ27: =IF($E27=0,"",$E27/STIG_Metrics!O27) | AK27: =IF($E27=0,"",$E27/STIG_Metrics!P27) | AL27: =IF($E27=0,"",$E27/STIG_Metrics!Q27)
D28: =(STIG_Metrics!A28) -> Canonical Ubuntu 20.04 LTS | E28: 0 | G28: =IF(E28=0,"",(AG28*24)*4) | H28: =IF(E28=0,"",PRODUCT($G28,$E$7)) | I28: =IF(E28=0,"",(AH28*24)*4) | J28: =IF(E28=0,"",PRODUCT($I28,$E$7)) | K28: =IF($E28=0,"",(STIG_Metrics!E28)*$E28) | L28: =IF($E28=0,"",(STIG_Metrics!F28)*$E28) | M28: =IF($E28=0,"",(STIG_Metrics!G28)*$E28) | N28: =IF($E28=0,"",(STIG_Metrics!H28)*$E28) | O28: =IF($E28=0,"",(STIG_Metrics!E28-STIG_Metrics!F28)*$E28) | P28: =IF($E28=0,"",(STIG_Metrics!E28-STIG_Metrics!G28)*$E28) | Q28: =IF($E28=0,"",(STIG_Metrics!E28-STIG_Metrics!H28)*$E28) | R28: =IF($E28=0,"",FLOOR($AC28*3,1)&" Days"&TEXT(SUM($AC28-TIME(8,0,0)*FLOOR($AC28*3,1))," h")&" Hrs") | S28: =IF($E28=0,"",FLOOR($AD28*3,1)&" Days"&TEXT(SUM($AD28-TIME(8,0,0)*FLOOR($AD28*3,1))," h")&" Hrs") | T28: =IF($E28=0,"",FLOOR($AE28*3,1)&" Days"&TEXT(SUM($AE28-TIME(8,0,0)*FLOOR($AE28*3,1))," h")&" Hrs") | U28: =IF($E28=0,"",FLOOR($AF28*3,1)& " Days"&TEXT(SUM($AF28-TIME(8,0,0)*FLOOR($AF28*3,1))," h") & " Hrs") | V28: =IF($E28=0,"",STIG_Metrics!R28) | W28: =IF($E28=0,"",STIG_Metrics!S28) | X28: =IF($E28=0,"",STIG_Metrics!T28) | Y28: =IF($E28=0,"",((K28*$E$8/60)*$E$7)) | Z28: =IF($E28=0,"",((O28*$E$8/60)*$E$7)) | AA28: =IF($E28=0,"",((P28*$E$8/60)*$E$7)) | AB28: =IF($E28=0,"",((Q28*$E$8/60)*$E$7)) | AC28: =IF($E28=0,"",IF(STIG_Metrics!N28=60,0,($E28/STIG_Metrics!N28)/24)) | AD28: =IF($E28=0,"",IF(STIG_Metrics!O28=60,0,($E28/STIG_Metrics!O28)/24)) | AE28: =IF($E28=0,"",IF(STIG_Metrics!P28=60,0,($E28/STIG_Metrics!P28)/24)) | AF28: =IF($E28=0,"",IF(STIG_Metrics!Q28=60,0,($E28/STIG_Metrics!Q28)/24)) | AG28: =IF($E28=0,"",$AD28-$AF28) | AH28: =IF($E28=0,"",$AE28-$AF28) | AI28: =IF($E28=0,"",$E28/STIG_Metrics!N28) | AJ28: =IF($E28=0,"",$E28/STIG_Metrics!O28) | AK28: =IF($E28=0,"",$E28/STIG_Metrics!P28) | AL28: =IF($E28=0,"",$E28/STIG_Metrics!Q28)
... D117: =(STIG_Metrics!A117) -> Windows Server 2008 R2 Member Server | E117: 0 | G117: =IF(E117=0,"",(AG117*24)*4) | H117: =IF(E117=0,"",PRODUCT($G117,$E$7)) | I117: =IF(E117=0,"",(AH117*24)*4) | J117: =IF(E117=0,"",PRODUCT($I117,$E$7)) | K117: =IF($E117=0,"",(STIG_Metrics!E117)*$E117) | L117: =IF($E117=0,"",(STIG_Metrics!F117)*$E117) | M117: =IF($E117=0,"",(STIG_Metrics!G117)*$E117) | N117: =IF($E117=0,"",(STIG_Metrics!H117)*$E117) | O117: =IF($E117=0,"",(STIG_Metrics!E117-STIG_Metrics!F117)*$E117) | P117: =IF($E117=0,"",(STIG_Metrics!E117-STIG_Metrics!G117)*$E117) | Q117: =IF($E117=0,"",(STIG_Metrics!E117-STIG_Metrics!H117)*$E117) | R117: =IF($E117=0,"",FLOOR($AC117*3,1)&" Days"&TEXT(SUM($AC117-TIME(8,0,0)*FLOOR($AC117*3,1))," h")&" Hrs") | S117: =IF($E117=0,"",FLOOR($AD117*3,1)&" Days"&TEXT(SUM($AD117-TIME(8,0,0)*FLOOR($AD117*3,1))," h")&" Hrs") | T117: =IF($E117=0,"",FLOOR($AE117*3,1)&" Days"&TEXT(SUM($AE117-TIME(8,0,0)*FLOOR($AE117*3,1))," h")&" Hrs") | U117: =IF($E117=0,"",FLOOR($AF117*3,1)& " Days"&TEXT(SUM($AF117-TIME(8,0,0)*FLOOR($AF117*3,1))," h") & " Hrs") | V117: =IF($E117=0,"",STIG_Metrics!R117) | W117: =IF($E117=0,"",STIG_Metrics!S117) | X117: =IF($E117=0,"",STIG_Metrics!T117) | Y117: =IF($E117=0,"",((K117*$E$8/60)*$E$7)) | Z117: =IF($E117=0,"",((O117*$E$8/60)*$E$7)) | AA117: =IF($E117=0,"",((P117*$E$8/60)*$E$7)) | AB117: =IF($E117=0,"",((Q117*$E$8/60)*$E$7)) | AC117: =IF($E117=0,"",IF(STIG_Metrics!N117=60,0,($E117/STIG_Metrics!N117)/24)) | AD117: =IF($E117=0,"",IF(STIG_Metrics!O117=60,0,($E117/STIG_Metrics!O117)/24)) | AE117: =IF($E117=0,"",IF(STIG_Metrics!P117=60,0,($E117/STIG_Metrics!P117)/24)) | AF117: =IF($E117=0,"",IF(STIG_Metrics!Q117=60,0,($E117/STIG_Metrics!Q117)/24)) | AG117: =IF($E117=0,"",$AD117-$AF117) | AH117: =IF($E117=0,"",$AE117-$AF117) | AI117: =IF($E117=0,"",$E117/STIG_Metrics!N117) | AJ117: =IF($E117=0,"",$E117/STIG_Metrics!O117) | AK117: =IF($E117=0,"",$E117/STIG_Metrics!P117) | AL117: =IF($E117=0,"",$E117/STIG_Metrics!Q117)
D118: [Hide this row] | AC118: =SUM(AC12:AC117) -> 4812.95 | AD118: =SUM(AD12:AD117) -> 854.7875 | AE118: =SUM(AE12:AE117) -> 576.32187 | AF118: =SUM(AF12:AF117) -> 105.12813 | AG118: =SUM(AG12:AG117) -> 749.65937 | AH118: =SUM(AH12:AH117) -> 471.19375 | AI118: =SUM(AI12:AI117) -> 115510.8 | AJ118: =SUM(AJ12:AJ117) -> 20548.15 | ... AL118: =SUM(AL12:AL117) -> 2675.975
D119: [Hide this row] | AC119: =AC118*3 -> 14438.85 | AD119: =AD118*3 -> 2564.3625 | AE119: =AE118*3 -> 1728.9656 | AF119: =AF118*3 -> 315.38438
L122: [Hide this column] | M122: [Hide this column] | N122: [Hide this column] | R122: [Hide this column] | V122: [Hide this column] | W122: [Hide this column] | X122: [Hide this column] | Y122: [Hide this column] | Z122: [Hide this column] | AA122: [Hide this column] | AB122: [Hide this column] | AC122: [Hide this column] | AD122: [Hide this column] | AE122: [Hide this column] | AF122: [Hide this column] | AG122: [Hide this column] | AH122: [Hide this column] | AI122: [Hide this column] | AJ122: [Hide this column] | AK122: [Hide this column] | AL122: [Hide this column] | AM122: [Hide this column] | AN122: [Hide this column] | AO122: [Hide this column] | AP122: [Hide this column] | AQ122: [Hide this column] | AR122: [Hide this column] | AS122: [Hide this column] | AT122: [Hide this column] | AU122: [Hide this column] | AV122: [Hide this column] | AW122: [Hide this column] | AX122: [Hide this column]

Sheet Charts
CJ2: Total Automated Checks
CL3: Total | CM3: Percentage | CN3: Label
CJ4: Total Checks | CL4: =Calculator!K7 -> 1540144 | CM4: =CL4/CL4 -> 1 | CN4: =CL4 -> 1540144
CJ5: DISA SCAP | CL5: =Calculator!L7 -> 1266612 | CM5: =CL5/CL4 -> 0.82239843 | CN5: =TEXT(CL5,"#,##")&CHAR(10)&" ("&TEXT(CM5,"0.0%")&")" -> 1,266,612 (82.2%)
CJ6: NIWC SCAP | CL6: =Calculator!M7 -> 1355721 | CM6: =CL6/CL4 -> 0.880256 | CN6: =TEXT(CL6,"#,##")&CHAR(10)&" ("&TEXT(CM6,"0.0%")&")" -> 1,355,721 (88.0%)
CJ7: Evaluate-STIG | CL7: =Calculator!N7 -> 1506503 | CM7: =CL7/CL4 -> 0.97815724 | CN7: =TEXT(CL7,"#,##")&CHAR(10)&" ("&TEXT(CM7,"0.0%")&")" -> 1,506,503 (97.8%)
CJ9: Total Non-Automated Checks (Remaining "NR")
CL10: Total | CM10: Percentage | CN10: Label
CJ11: Total Checks | CL11: =Calculator!K7 -> 1540144 | CM11: =CL11/CL11 -> 1 | CN11: =CL11 -> 1540144
CJ12: DISA SCAP | CL12: =Calculator!O7 -> 273532 | CM12: =CL12/CL11 -> 0.17760157 | CN12: =TEXT(CL12,"#,##")&CHAR(10)&" ("&TEXT(CM12,"0.0%")&")" -> 273,532 (17.8%)
CJ13: NIWC SCAP | CL13: =Calculator!P7 -> 184423 | CM13: =CL13/CL11 -> 0.119744 | CN13: =TEXT(CL13,"#,##")&CHAR(10)&" ("&TEXT(CM13,"0.0%")&")" -> 184,423 (12.0%)
CJ14: Evaluate-STIG | CL14: =Calculator!Q7 -> 33641 | CM14: =CL14/CL11 -> 0.021842763 | CN14: =TEXT(CL14,"#,##")&CHAR(10)&" ("&TEXT(CM14,"0.0%")&")" -> 33,641 (2.2%)
CI30: Annual Cost Avoidance Over Manual Review
CJ31: DISA SCAP | CK31: NIWC SCAP | CL31: Evaluate-STIG | CM31: Avoidance Over DISA SCAP | CN31: Avoidance Over NIWC SCAP | CO31: Label
CI32: Q1 | CJ32: =Calculator!AU12 -> 11969483 | CK32: =Calculator!AU13 -> 12811563 | CL32: =Calculator!AU14 -> 14236453 | CM32: =CJ32+((CL32-CJ32)/2) -> 13102968 | CN32: =CK32+((CL32-CK32)/2) -> 13524008 | CO32: =CL32-CJ32 -> 2266970
CI33: Q2 | CJ33: =Calculator!AV12 -> 23938967 | CK33: =Calculator!AV13 -> 25623127 | CL33: =Calculator!AV14 -> 28472907 | CM33: =CJ33+((CL33-CJ33)/2) -> 26205937 | CN33: =CK33+((CL33-CK33)/2) -> 27048017 | CO33: =CL33-CJ33 -> 4533939.9
CI34: Q3 | CJ34: =Calculator!AW12 -> 35908450 | CK34: =Calculator!AW13 -> 38434690 | CL34: =Calculator!AW14 -> 42709360 | CM34: =CJ34+((CL34-CJ34)/2) -> 39308905 | CN34: =CK34+((CL34-CK34)/2) -> 40572025 | CO34: =CL34-CJ34 -> 6800909.9
CI35: Q4 | CJ35: =Calculator!AX12 -> 47877934 | CK35: =Calculator!AX13 -> 51246254 | CL35: =Calculator!AX14 -> 56945813 | CM35: =CJ35+((CL35-CJ35)/2) -> 52411873 | CN35: =CK35+((CL35-CK35)/2) -> 54096034 | CO35: =CL35-CJ35 -> 9067879.8

Sheet STIG_Metrics
A1: Evaluate-STIG Per-Checklist Metrics (Out-of-Box Configuration / "Unclassified" ScanType / Evaluate-STIG Path to "NF") Updated: 12/10/2025
A2: This row intentially blank
A3: This row intentially blank
A4: This row intentially blank
A5: This row intentially blank
A6: This row intentially blank
A7: This row intentially blank
A8: This row intentially blank
A9: This row intentially blank
A10: This row intentially blank
A11: STIG Supported by Evaluate-STIG | B11: DISA STIG Status | C11: DISA Benchmark Available | D11: NIWC Enhanced Benchmark Available | E11: Total STIG Checks | F11: Total Completed Checks: DISA SCAP | G11: Total Completed Checks: NIWC Enhanced SCAP | H11: Total Completed Checks: Evaluate-STIG | I11: Total Completed Checks: Evaluate-STIG Over DISA SCAP | J11: Total Completed Checks: Evaluate-STIG Over NIWC Enhanced SCAP | K11: Time to Complete (Minutes): Manual | L11: Time Savings (Minutes): Evaluate-STIG Over DISA SCAP | M11: Time Savings (Minutes): Evaluate-STIG Over NIWC Enhanced SCAP | N11: STIGS Per Hour: Manual | O11: STIGS Per Hour: DISA SCAP | P11: STIGS Per Hour: NIWC Enhanced SCAP | Q11: STIGS Per Hour: Evaluate-STIG | R11: Productivity Gain: DISA SCAP over Manual | S11: Productivity Gain: NIWC Enhanced SCAP over Manual | T11: Productivity Gain: Evaluate-STIG Over Manual | U11: Productivity Gain: Evaluate-STIG Over DISA SCAP | V11: Productivity Gain: Evaluate-STIG Over NIWC Enhanced SCAP | W11: CKL Completion (Finalized Checks): DISA SCAP | X11: CKL Completion (Finalized Checks): NIWC SCAP | Y11: CKL Completion (Finalized Checks): Evaluate-STIG | AA11: DISA Status Dropdown
A12: Active Directory Domain | B12: Active | E12: 36 | F12: 0 | G12: 0 | H12: 20 | I12: =H12-F12 -> 20 | J12: =H12-G12 -> 20 | K12: =PRODUCT($E12,Calculator!$E$8) -> 162 | L12: =PRODUCT($I12,Calculator!$E$8) -> 90 | M12: =PRODUCT($J12,Calculator!$E$8) -> 90 | N12: =60/($E12*Calculator!$E$8) -> 0.37037037 | O12: =IF(($E12=$F12),60,60/(($E12-$F12)*Calculator!$E$8)) -> 0.37037037 | P12: =IF(($E12=$G12),60,60/(($E12-$G12)*Calculator!$E$8)) -> 0.37037037 | Q12: =IF(($E12=$H12),60,60/(($E12-$H12)*Calculator!$E$8)) -> 0.83333333 | R12: =(O12-N12)/N12 -> 0 | S12: =(P12-N12)/N12 -> 0 | T12: =(Q12-N12)/N12 -> 1.25 | U12: =(Q12-O12)/O12 -> 1.25 | V12: =(Q12-P12)/P12 -> 1.25 | W12: =F12/E12 -> 0 | X12: =G12/E12 -> 0 | Y12: =H12/E12 -> 0.55555556 | AA12: Active
A13: Active Directory Forest | B13: Active | E13: 7 | F13: 0 | G13: 0 | H13: 3 | I13: =H13-F13 -> 3 | J13: =H13-G13 -> 3 | K13: =PRODUCT($E13,Calculator!$E$8) -> 31.5 | L13: =PRODUCT($I13,Calculator!$E$8) -> 13.5 | M13: =PRODUCT($J13,Calculator!$E$8) -> 13.5 | N13: =60/($E13*Calculator!$E$8) -> 1.9047619 | O13: =IF(($E13=$F13),60,60/(($E13-$F13)*Calculator!$E$8)) -> 1.9047619 | P13: =IF(($E13=$G13),60,60/(($E13-$G13)*Calculator!$E$8)) -> 1.9047619 | Q13: =IF(($E13=$H13),60,60/(($E13-$H13)*Calculator!$E$8)) -> 3.3333333 | R13: =(O13-N13)/N13 -> 0 | S13: =(P13-N13)/N13 -> 0 | T13: =(Q13-N13)/N13 -> 0.75 | U13: =(Q13-O13)/O13 -> 0.75 | V13: =(Q13-P13)/P13 -> 0.75 | W13: =F13/E13 -> 0 | X13: =G13/E13 -> 0 | Y13: =H13/E13 -> 0.42857143 | AA13: Sunset
A14: Adobe Acrobat Pro XI | B14: Deprecated | E14: 26 | F14: 0 | G14: 0 | H14: 25 | I14: =H14-F14 -> 25 | J14: =H14-G14 -> 25 | K14: =PRODUCT($E14,Calculator!$E$8) -> 117 | L14: =PRODUCT($I14,Calculator!$E$8) -> 112.5 | M14: =PRODUCT($J14,Calculator!$E$8) -> 112.5 | N14: =60/($E14*Calculator!$E$8) -> 0.51282051 | O14: =IF(($E14=$F14),60,60/(($E14-$F14)*Calculator!$E$8)) -> 0.51282051 | P14: =IF(($E14=$G14),60,60/(($E14-$G14)*Calculator!$E$8)) -> 0.51282051 | Q14: =IF(($E14=$H14),60,60/(($E14-$H14)*Calculator!$E$8)) -> 13.333333 | R14: =(O14-N14)/N14 -> 0 | S14: =(P14-N14)/N14 -> 0 | T14: =(Q14-N14)/N14 -> 25 | U14: =(Q14-O14)/O14 -> 25 | V14: =(Q14-P14)/P14 -> 25 | W14: =F14/E14 -> 0 | X14: =G14/E14 -> 0 | Y14: =H14/E14 -> 0.96153846 | AA14: Deprecated
A15: Adobe Acrobat Professional DC Classic Track | B15: Deprecated | E15: 23 | F15: 0 | G15: 0 | H15: 23 | I15: =H15-F15 -> 23 | J15: =H15-G15 -> 23 | K15: =PRODUCT($E15,Calculator!$E$8) -> 103.5 | L15: =PRODUCT($I15,Calculator!$E$8) -> 103.5 | M15: =PRODUCT($J15,Calculator!$E$8) -> 103.5 | N15: =60/($E15*Calculator!$E$8) -> 0.57971014 | O15: =IF(($E15=$F15),60,60/(($E15-$F15)*Calculator!$E$8)) -> 0.57971014 | P15: =IF(($E15=$G15),60,60/(($E15-$G15)*Calculator!$E$8)) -> 0.57971014 | Q15: =IF(($E15=$H15),60,60/(($E15-$H15)*Calculator!$E$8)) -> 60 | R15: =(O15-N15)/N15 -> 0 | S15: =(P15-N15)/N15 -> 0 | T15: =(Q15-N15)/N15 -> 102.5 | U15: =(Q15-O15)/O15 -> 102.5 | V15: =(Q15-P15)/P15 -> 102.5 | W15: =F15/E15 -> 0 | X15: =G15/E15 -> 0 | Y15: =H15/E15 -> 1
A16: Adobe Acrobat Professional DC Continuous Track | B16: Active | E16: 23 | F16: 0 | G16: 0 | H16: 22 | I16: =H16-F16 -> 22 | J16: =H16-G16 -> 22 | K16: =PRODUCT($E16,Calculator!$E$8) -> 103.5 | L16: =PRODUCT($I16,Calculator!$E$8) -> 99 | M16: =PRODUCT($J16,Calculator!$E$8) -> 99 | N16: =60/($E16*Calculator!$E$8) -> 0.57971014 | O16: =IF(($E16=$F16),60,60/(($E16-$F16)*Calculator!$E$8)) -> 0.57971014 | P16: =IF(($E16=$G16),60,60/(($E16-$G16)*Calculator!$E$8)) -> 0.57971014 | Q16: =IF(($E16=$H16),60,60/(($E16-$H16)*Calculator!$E$8)) -> 13.333333 | R16: =(O16-N16)/N16 -> 0 | S16: =(P16-N16)/N16 -> 0 | T16: =(Q16-N16)/N16 -> 22 | U16: =(Q16-O16)/O16 -> 22 | V16: =(Q16-P16)/P16 -> 22 | W16: =F16/E16 -> 0 | X16: =G16/E16 -> 0 | Y16: =H16/E16 -> 0.95652174
A17: Adobe Acrobat Reader DC Classic Track | B17: Deprecated | E17: 26 | F17: 0 | G17: 0 | H17: 26 | I17: =H17-F17 -> 26 | J17: =H17-G17 -> 26 | K17: =PRODUCT($E17,Calculator!$E$8) -> 117 | L17: =PRODUCT($I17,Calculator!$E$8) -> 117 | M17: =PRODUCT($J17,Calculator!$E$8) -> 117 | N17: =60/($E17*Calculator!$E$8) -> 0.51282051 | O17: =IF(($E17=$F17),60,60/(($E17-$F17)*Calculator!$E$8)) -> 0.51282051 | P17: =IF(($E17=$G17),60,60/(($E17-$G17)*Calculator!$E$8)) -> 0.51282051 | Q17: =IF(($E17=$H17),60,60/(($E17-$H17)*Calculator!$E$8)) -> 60 | R17: =(O17-N17)/N17 -> 0 | S17: =(P17-N17)/N17 -> 0 | T17: =(Q17-N17)/N17 -> 116 | U17: =(Q17-O17)/O17 -> 116 | V17: =(Q17-P17)/P17 -> 116 | W17: =F17/E17 -> 0 | X17: =G17/E17 -> 0 | Y17: =H17/E17 -> 1
A18: Adobe Acrobat Reader DC Continuous Track | B18: Active | C18: P | D18: P | E18: 26 | F18: 22 | G18: 25 | H18: 25 | I18: =H18-F18 -> 3 | J18: =H18-G18 -> 0 | K18: =PRODUCT($E18,Calculator!$E$8) -> 117 | L18: =PRODUCT($I18,Calculator!$E$8) -> 13.5 | M18: =PRODUCT($J18,Calculator!$E$8) -> 0 | N18: =60/($E18*Calculator!$E$8) -> 0.51282051 | O18: =IF(($E18=$F18),60,60/(($E18-$F18)*Calculator!$E$8)) -> 3.3333333 | P18: =IF(($E18=$G18),60,60/(($E18-$G18)*Calculator!$E$8)) -> 13.333333 | Q18: =IF(($E18=$H18),60,60/(($E18-$H18)*Calculator!$E$8)) -> 13.333333 | R18: =(O18-N18)/N18 -> 5.5 | S18: =(P18-N18)/N18 -> 25 | T18: =(Q18-N18)/N18 -> 25 | U18: =(Q18-O18)/O18 -> 3 | V18: =(Q18-P18)/P18 -> 0 | W18: =F18/E18 -> 0.84615385 | X18: =G18/E18 -> 0.96153846 | Y18: =H18/E18 -> 0.96153846
A19: Amazon Linux 2023 | B19: Active | E19: 192 | F19: 0 | G19: 0 | H19: 178 | I19: =H19-F19 -> 178 | J19: =H19-G19 -> 178 | K19: =PRODUCT($E19,Calculator!$E$8) -> 864 | L19: =PRODUCT($I19,Calculator!$E$8) -> 801 | M19: =PRODUCT($J19,Calculator!$E$8) -> 801 | N19: =60/($E19*Calculator!$E$8) -> 0.069444444 | O19: =IF(($E19=$F19),60,60/(($E19-$F19)*Calculator!$E$8)) -> 0.069444444 | P19: =IF(($E19=$G19),60,60/(($E19-$G19)*Calculator!$E$8)) -> 0.069444444 | Q19: =IF(($E19=$H19),60,60/(($E19-$H19)*Calculator!$E$8)) -> 0.95238095 | R19: =(O19-N19)/N19 -> 0 | S19: =(P19-N19)/N19 -> 0 | T19: =(Q19-N19)/N19 -> 12.714286 | U19: =(Q19-O19)/O19 -> 12.714286 | V19: =(Q19-P19)/P19 -> 12.714286 | W19: =F19/E19 -> 0 | X19: =G19/E19 -> 0 | Y19: =H19/E19 -> 0.92708333
A20: Apache Server 2.4 UNIX Server | B20: Active | E20: 47 | F20: 0 | G20: 0 | H20: 23 | I20: =H20-F20 -> 23 | J20: =H20-G20 -> 23 | K20: =PRODUCT($E20,Calculator!$E$8) -> 211.5 | L20: =PRODUCT($I20,Calculator!$E$8) -> 103.5 | M20: =PRODUCT($J20,Calculator!$E$8) -> 103.5 | N20: =60/($E20*Calculator!$E$8) -> 0.28368794 | O20: =IF(($E20=$F20),60,60/(($E20-$F20)*Calculator!$E$8)) -> 0.28368794 | P20: =IF(($E20=$G20),60,60/(($E20-$G20)*Calculator!$E$8)) -> 0.28368794 | Q20: =IF(($E20=$H20),60,60/(($E20-$H20)*Calculator!$E$8)) -> 0.55555556 | R20: =(O20-N20)/N20 -> 0 | S20: =(P20-N20)/N20 -> 0 | T20: =(Q20-N20)/N20 -> 0.95833333 | U20: =(Q20-O20)/O20 -> 0.95833333 | V20: =(Q20-P20)/P20 -> 0.95833333 | W20: =F20/E20 -> 0 | X20: =G20/E20 -> 0 | Y20: =H20/E20 -> 0.4893617
A21: Apache Server 2.4 UNIX Site | B21: Active | E21: 27 | F21: 0 | G21: 0 | H21: 16 | I21: =H21-F21 -> 16 | J21: =H21-G21 -> 16 | K21: =PRODUCT($E21,Calculator!$E$8) -> 121.5 | L21: =PRODUCT($I21,Calculator!$E$8) -> 72 | M21: =PRODUCT($J21,Calculator!$E$8) -> 72 | N21: =60/($E21*Calculator!$E$8) -> 0.49382716 | O21: =IF(($E21=$F21),60,60/(($E21-$F21)*Calculator!$E$8)) -> 0.49382716 | P21: =IF(($E21=$G21),60,60/(($E21-$G21)*Calculator!$E$8)) -> 0.49382716 | Q21: =IF(($E21=$H21),60,60/(($E21-$H21)*Calculator!$E$8)) -> 1.2121212 | R21: =(O21-N21)/N21 -> 0 | S21: =(P21-N21)/N21 -> 0 | T21: =(Q21-N21)/N21 -> 1.4545455 | U21: =(Q21-O21)/O21 -> 1.4545455 | V21: =(Q21-P21)/P21 -> 1.4545455 | W21: =F21/E21 -> 0 | X21: =G21/E21 -> 0 | Y21: =H21/E21 -> 0.59259259
A22: Apache Server 2.4 Windows Server | B22: Active | E22: 54 | F22: 0 | G22: 0 | H22: 25 | I22: =H22-F22 -> 25 | J22: =H22-G22 -> 25 | K22: =PRODUCT($E22,Calculator!$E$8) -> 243 | L22: =PRODUCT($I22,Calculator!$E$8) -> 112.5 | M22: =PRODUCT($J22,Calculator!$E$8) -> 112.5 | N22: =60/($E22*Calculator!$E$8) -> 0.24691358 | O22: =IF(($E22=$F22),60,60/(($E22-$F22)*Calculator!$E$8)) -> 0.24691358 | P22: =IF(($E22=$G22),60,60/(($E22-$G22)*Calculator!$E$8)) -> 0.24691358 | Q22: =IF(($E22=$H22),60,60/(($E22-$H22)*Calculator!$E$8)) -> 0.45977011 | R22: =(O22-N22)/N22 -> 0 | S22: =(P22-N22)/N22 -> 0 | T22: =(Q22-N22)/N22 -> 0.86206897 | U22: =(Q22-O22)/O22 -> 0.86206897 | V22: =(Q22-P22)/P22 -> 0.86206897 | W22: =F22/E22 -> 0 | X22: =G22/E22 -> 0 | Y22: =H22/E22 -> 0.46296296
A23: Apache Server 2.4 Windows Site | B23: Active | E23: 36 | F23: 0 | G23: 0 | H23: 21 | I23: =H23-F23 -> 21 | J23: =H23-G23 -> 21 | K23: =PRODUCT($E23,Calculator!$E$8) -> 162 | L23: =PRODUCT($I23,Calculator!$E$8) -> 94.5 | M23: =PRODUCT($J23,Calculator!$E$8) -> 94.5 | N23: =60/($E23*Calculator!$E$8) -> 0.37037037 | O23: =IF(($E23=$F23),60,60/(($E23-$F23)*Calculator!$E$8)) -> 0.37037037 | P23: =IF(($E23=$G23),60,60/(($E23-$G23)*Calculator!$E$8)) -> 0.37037037 | Q23: =IF(($E23=$H23),60,60/(($E23-$H23)*Calculator!$E$8)) -> 0.88888889 | R23: =(O23-N23)/N23 -> 0 | S23: =(P23-N23)/N23 -> 0 | T23: =(Q23-N23)/N23 -> 1.4 | U23: =(Q23-O23)/O23 -> 1.4 | V23: =(Q23-P23)/P23 -> 1.4 | W23: =F23/E23 -> 0 | X23: =G23/E23 -> 0 | Y23: =H23/E23 -> 0.58333333
A24: Apache Tomcat Application Server 9 | B24: Active | E24: 79 | F24: 0 | G24: 0 | H24: 71 | I24: =H24-F24 -> 71 | J24: =H24-G24 -> 71 | K24: =PRODUCT($E24,Calculator!$E$8) -> 355.5 | L24: =PRODUCT($I24,Calculator!$E$8) -> 319.5 | M24: =PRODUCT($J24,Calculator!$E$8) -> 319.5 | N24: =60/($E24*Calculator!$E$8) -> 0.16877637 | O24: =IF(($E24=$F24),60,60/(($E24-$F24)*Calculator!$E$8)) -> 0.16877637 | P24: =IF(($E24=$G24),60,60/(($E24-$G24)*Calculator!$E$8)) -> 0.16877637 | Q24: =IF(($E24=$H24),60,60/(($E24-$H24)*Calculator!$E$8)) -> 1.6666667 | R24: =(O24-N24)/N24 -> 0 | S24: =(P24-N24)/N24 -> 0 | T24: =(Q24-N24)/N24 -> 8.875 | U24: =(Q24-O24)/O24 -> 8.875 | V24: =(Q24-P24)/P24 -> 8.875 | W24: =F24/E24 -> 0 | X24: =G24/E24 -> 0 | Y24: =H24/E24 -> 0.89873418
A25: ArcGIS for Server 10.3 | B25: Sunset | E25: 23 | F25: 0 | G25: 0 | H25: 15 | I25: =H25-F25 -> 15 | J25: =H25-G25 -> 15 | K25: =PRODUCT($E25,Calculator!$E$8) -> 103.5 | L25: =PRODUCT($I25,Calculator!$E$8) -> 67.5 | M25: =PRODUCT($J25,Calculator!$E$8) -> 67.5 | N25: =60/($E25*Calculator!$E$8) -> 0.57971014 | O25: =IF(($E25=$F25),60,60/(($E25-$F25)*Calculator!$E$8)) -> 0.57971014 | P25: =IF(($E25=$G25),60,60/(($E25-$G25)*Calculator!$E$8)) -> 0.57971014 | Q25: =IF(($E25=$H25),60,60/(($E25-$H25)*Calculator!$E$8)) -> 1.6666667 | R25: =(O25-N25)/N25 -> 0 | S25: =(P25-N25)/N25 -> 0 | T25: =(Q25-N25)/N25 -> 1.875 | U25: =(Q25-O25)/O25 -> 1.875 | V25: =(Q25-P25)/P25 -> 1.875 | W25: =F25/E25 -> 0 | X25: =G25/E25 -> 0 | Y25: =H25/E25 -> 0.65217391
